Traceback (most recent call last):
  File "C:\Users\crist\anaconda3\lib\site-packages\jupyter_cache\executors\utils.py", line 58, in single_nb_execution
    executenb(
  File "C:\Users\crist\anaconda3\lib\site-packages\nbclient\client.py", line 1112, in execute
    return NotebookClient(nb=nb, resources=resources, km=km, **kwargs).execute()
  File "C:\Users\crist\anaconda3\lib\site-packages\nbclient\util.py", line 74, in wrapped
    return just_run(coro(*args, **kwargs))
  File "C:\Users\crist\anaconda3\lib\site-packages\nbclient\util.py", line 53, in just_run
    return loop.run_until_complete(coro)
  File "C:\Users\crist\anaconda3\lib\asyncio\base_events.py", line 642, in run_until_complete
    return future.result()
  File "C:\Users\crist\anaconda3\lib\site-packages\nbclient\client.py", line 553, in async_execute
    await self.async_execute_cell(
  File "C:\Users\crist\anaconda3\lib\site-packages\nbclient\client.py", line 857, in async_execute_cell
    self._check_raise_for_error(cell, exec_reply)
  File "C:\Users\crist\anaconda3\lib\site-packages\nbclient\client.py", line 760, in _check_raise_for_error
    raise CellExecutionError.from_cell_and_msg(cell, exec_reply_content)
nbclient.exceptions.CellExecutionError: An error occurred while executing the following cell:
------------------
# Installations for Google Collab - Uncomment if running through Collab

%%capture
import sys
import os

#!pip install pyomo
!pip install idaes-pse --pre
!idaes get-extensions --to ./bin 
os.environ['PATH'] += ':bin'

##############################################################################

# Imports
from __future__ import division
from fileinput import filename
from pyomo.environ import *
from pyomo.core import *
from pyomo.opt import SolverFactory
import pandas as pd
import numpy as np
import math
import random
from Objective_Function import ObjectiveFunction_rule
from Model_Constraints import *
#from Model_Debugging_Tools import Variable_Frame
#from Model_Sel_Res import Selected_Results

import matplotlib.pyplot as plt
import plotly.express as px
import plotly.graph_objects as go
from plotly.subplots import make_subplots


------------------


UsageError: Line magic function `%%capture` not found.

